{
 "cells": [
  {
   "cell_type": "code",
   "execution_count": 1,
   "metadata": {},
   "outputs": [
    {
     "ename": "ImportError",
     "evalue": "Traceback (most recent call last):\n  File \"C:\\Users\\kingjy79\\anaconda\\lib\\site-packages\\tensorflow\\python\\pywrap_tensorflow_internal.py\", line 14, in swig_import_helper\n    return importlib.import_module(mname)\n  File \"C:\\Users\\kingjy79\\anaconda\\lib\\importlib\\__init__.py\", line 126, in import_module\n    return _bootstrap._gcd_import(name[level:], package, level)\n  File \"<frozen importlib._bootstrap>\", line 985, in _gcd_import\n  File \"<frozen importlib._bootstrap>\", line 968, in _find_and_load\n  File \"<frozen importlib._bootstrap>\", line 957, in _find_and_load_unlocked\n  File \"<frozen importlib._bootstrap>\", line 666, in _load_unlocked\n  File \"<frozen importlib._bootstrap>\", line 577, in module_from_spec\n  File \"<frozen importlib._bootstrap_external>\", line 938, in create_module\n  File \"<frozen importlib._bootstrap>\", line 222, in _call_with_frames_removed\nImportError: DLL load failed: 지정된 모듈을 찾을 수 없습니다.\n\nDuring handling of the above exception, another exception occurred:\n\nTraceback (most recent call last):\n  File \"C:\\Users\\kingjy79\\anaconda\\lib\\site-packages\\tensorflow\\python\\pywrap_tensorflow.py\", line 58, in <module>\n    from tensorflow.python.pywrap_tensorflow_internal import *\n  File \"C:\\Users\\kingjy79\\anaconda\\lib\\site-packages\\tensorflow\\python\\pywrap_tensorflow_internal.py\", line 17, in <module>\n    _pywrap_tensorflow_internal = swig_import_helper()\n  File \"C:\\Users\\kingjy79\\anaconda\\lib\\site-packages\\tensorflow\\python\\pywrap_tensorflow_internal.py\", line 16, in swig_import_helper\n    return importlib.import_module('_pywrap_tensorflow_internal')\n  File \"C:\\Users\\kingjy79\\anaconda\\lib\\importlib\\__init__.py\", line 126, in import_module\n    return _bootstrap._gcd_import(name[level:], package, level)\nImportError: No module named '_pywrap_tensorflow_internal'\n\n\nFailed to load the native TensorFlow runtime.\n\nSee https://www.tensorflow.org/install/install_sources#common_installation_problems\n\nfor some common reasons and solutions.  Include the entire stack trace\nabove this error message when asking for help.",
     "output_type": "error",
     "traceback": [
      "\u001b[1;31m---------------------------------------------------------------------------\u001b[0m",
      "\u001b[1;31mImportError\u001b[0m                               Traceback (most recent call last)",
      "\u001b[1;32m~\\anaconda\\lib\\site-packages\\tensorflow\\python\\pywrap_tensorflow_internal.py\u001b[0m in \u001b[0;36mswig_import_helper\u001b[1;34m()\u001b[0m\n\u001b[0;32m     13\u001b[0m         \u001b[1;32mtry\u001b[0m\u001b[1;33m:\u001b[0m\u001b[1;33m\u001b[0m\u001b[0m\n\u001b[1;32m---> 14\u001b[1;33m             \u001b[1;32mreturn\u001b[0m \u001b[0mimportlib\u001b[0m\u001b[1;33m.\u001b[0m\u001b[0mimport_module\u001b[0m\u001b[1;33m(\u001b[0m\u001b[0mmname\u001b[0m\u001b[1;33m)\u001b[0m\u001b[1;33m\u001b[0m\u001b[0m\n\u001b[0m\u001b[0;32m     15\u001b[0m         \u001b[1;32mexcept\u001b[0m \u001b[0mImportError\u001b[0m\u001b[1;33m:\u001b[0m\u001b[1;33m\u001b[0m\u001b[0m\n",
      "\u001b[1;32m~\\anaconda\\lib\\importlib\\__init__.py\u001b[0m in \u001b[0;36mimport_module\u001b[1;34m(name, package)\u001b[0m\n\u001b[0;32m    125\u001b[0m             \u001b[0mlevel\u001b[0m \u001b[1;33m+=\u001b[0m \u001b[1;36m1\u001b[0m\u001b[1;33m\u001b[0m\u001b[0m\n\u001b[1;32m--> 126\u001b[1;33m     \u001b[1;32mreturn\u001b[0m \u001b[0m_bootstrap\u001b[0m\u001b[1;33m.\u001b[0m\u001b[0m_gcd_import\u001b[0m\u001b[1;33m(\u001b[0m\u001b[0mname\u001b[0m\u001b[1;33m[\u001b[0m\u001b[0mlevel\u001b[0m\u001b[1;33m:\u001b[0m\u001b[1;33m]\u001b[0m\u001b[1;33m,\u001b[0m \u001b[0mpackage\u001b[0m\u001b[1;33m,\u001b[0m \u001b[0mlevel\u001b[0m\u001b[1;33m)\u001b[0m\u001b[1;33m\u001b[0m\u001b[0m\n\u001b[0m\u001b[0;32m    127\u001b[0m \u001b[1;33m\u001b[0m\u001b[0m\n",
      "\u001b[1;32m~\\anaconda\\lib\\importlib\\_bootstrap.py\u001b[0m in \u001b[0;36m_gcd_import\u001b[1;34m(name, package, level)\u001b[0m\n",
      "\u001b[1;32m~\\anaconda\\lib\\importlib\\_bootstrap.py\u001b[0m in \u001b[0;36m_find_and_load\u001b[1;34m(name, import_)\u001b[0m\n",
      "\u001b[1;32m~\\anaconda\\lib\\importlib\\_bootstrap.py\u001b[0m in \u001b[0;36m_find_and_load_unlocked\u001b[1;34m(name, import_)\u001b[0m\n",
      "\u001b[1;32m~\\anaconda\\lib\\importlib\\_bootstrap.py\u001b[0m in \u001b[0;36m_load_unlocked\u001b[1;34m(spec)\u001b[0m\n",
      "\u001b[1;32m~\\anaconda\\lib\\importlib\\_bootstrap.py\u001b[0m in \u001b[0;36mmodule_from_spec\u001b[1;34m(spec)\u001b[0m\n",
      "\u001b[1;32m~\\anaconda\\lib\\importlib\\_bootstrap_external.py\u001b[0m in \u001b[0;36mcreate_module\u001b[1;34m(self, spec)\u001b[0m\n",
      "\u001b[1;32m~\\anaconda\\lib\\importlib\\_bootstrap.py\u001b[0m in \u001b[0;36m_call_with_frames_removed\u001b[1;34m(f, *args, **kwds)\u001b[0m\n",
      "\u001b[1;31mImportError\u001b[0m: DLL load failed: 지정된 모듈을 찾을 수 없습니다.",
      "\nDuring handling of the above exception, another exception occurred:\n",
      "\u001b[1;31mImportError\u001b[0m                               Traceback (most recent call last)",
      "\u001b[1;32m~\\anaconda\\lib\\site-packages\\tensorflow\\python\\pywrap_tensorflow.py\u001b[0m in \u001b[0;36m<module>\u001b[1;34m()\u001b[0m\n\u001b[0;32m     57\u001b[0m \u001b[1;33m\u001b[0m\u001b[0m\n\u001b[1;32m---> 58\u001b[1;33m   \u001b[1;32mfrom\u001b[0m \u001b[0mtensorflow\u001b[0m\u001b[1;33m.\u001b[0m\u001b[0mpython\u001b[0m\u001b[1;33m.\u001b[0m\u001b[0mpywrap_tensorflow_internal\u001b[0m \u001b[1;32mimport\u001b[0m \u001b[1;33m*\u001b[0m\u001b[1;33m\u001b[0m\u001b[0m\n\u001b[0m\u001b[0;32m     59\u001b[0m   \u001b[1;32mfrom\u001b[0m \u001b[0mtensorflow\u001b[0m\u001b[1;33m.\u001b[0m\u001b[0mpython\u001b[0m\u001b[1;33m.\u001b[0m\u001b[0mpywrap_tensorflow_internal\u001b[0m \u001b[1;32mimport\u001b[0m \u001b[0m__version__\u001b[0m\u001b[1;33m\u001b[0m\u001b[0m\n",
      "\u001b[1;32m~\\anaconda\\lib\\site-packages\\tensorflow\\python\\pywrap_tensorflow_internal.py\u001b[0m in \u001b[0;36m<module>\u001b[1;34m()\u001b[0m\n\u001b[0;32m     16\u001b[0m             \u001b[1;32mreturn\u001b[0m \u001b[0mimportlib\u001b[0m\u001b[1;33m.\u001b[0m\u001b[0mimport_module\u001b[0m\u001b[1;33m(\u001b[0m\u001b[1;34m'_pywrap_tensorflow_internal'\u001b[0m\u001b[1;33m)\u001b[0m\u001b[1;33m\u001b[0m\u001b[0m\n\u001b[1;32m---> 17\u001b[1;33m     \u001b[0m_pywrap_tensorflow_internal\u001b[0m \u001b[1;33m=\u001b[0m \u001b[0mswig_import_helper\u001b[0m\u001b[1;33m(\u001b[0m\u001b[1;33m)\u001b[0m\u001b[1;33m\u001b[0m\u001b[0m\n\u001b[0m\u001b[0;32m     18\u001b[0m     \u001b[1;32mdel\u001b[0m \u001b[0mswig_import_helper\u001b[0m\u001b[1;33m\u001b[0m\u001b[0m\n",
      "\u001b[1;32m~\\anaconda\\lib\\site-packages\\tensorflow\\python\\pywrap_tensorflow_internal.py\u001b[0m in \u001b[0;36mswig_import_helper\u001b[1;34m()\u001b[0m\n\u001b[0;32m     15\u001b[0m         \u001b[1;32mexcept\u001b[0m \u001b[0mImportError\u001b[0m\u001b[1;33m:\u001b[0m\u001b[1;33m\u001b[0m\u001b[0m\n\u001b[1;32m---> 16\u001b[1;33m             \u001b[1;32mreturn\u001b[0m \u001b[0mimportlib\u001b[0m\u001b[1;33m.\u001b[0m\u001b[0mimport_module\u001b[0m\u001b[1;33m(\u001b[0m\u001b[1;34m'_pywrap_tensorflow_internal'\u001b[0m\u001b[1;33m)\u001b[0m\u001b[1;33m\u001b[0m\u001b[0m\n\u001b[0m\u001b[0;32m     17\u001b[0m     \u001b[0m_pywrap_tensorflow_internal\u001b[0m \u001b[1;33m=\u001b[0m \u001b[0mswig_import_helper\u001b[0m\u001b[1;33m(\u001b[0m\u001b[1;33m)\u001b[0m\u001b[1;33m\u001b[0m\u001b[0m\n",
      "\u001b[1;32m~\\anaconda\\lib\\importlib\\__init__.py\u001b[0m in \u001b[0;36mimport_module\u001b[1;34m(name, package)\u001b[0m\n\u001b[0;32m    125\u001b[0m             \u001b[0mlevel\u001b[0m \u001b[1;33m+=\u001b[0m \u001b[1;36m1\u001b[0m\u001b[1;33m\u001b[0m\u001b[0m\n\u001b[1;32m--> 126\u001b[1;33m     \u001b[1;32mreturn\u001b[0m \u001b[0m_bootstrap\u001b[0m\u001b[1;33m.\u001b[0m\u001b[0m_gcd_import\u001b[0m\u001b[1;33m(\u001b[0m\u001b[0mname\u001b[0m\u001b[1;33m[\u001b[0m\u001b[0mlevel\u001b[0m\u001b[1;33m:\u001b[0m\u001b[1;33m]\u001b[0m\u001b[1;33m,\u001b[0m \u001b[0mpackage\u001b[0m\u001b[1;33m,\u001b[0m \u001b[0mlevel\u001b[0m\u001b[1;33m)\u001b[0m\u001b[1;33m\u001b[0m\u001b[0m\n\u001b[0m\u001b[0;32m    127\u001b[0m \u001b[1;33m\u001b[0m\u001b[0m\n",
      "\u001b[1;31mImportError\u001b[0m: No module named '_pywrap_tensorflow_internal'",
      "\nDuring handling of the above exception, another exception occurred:\n",
      "\u001b[1;31mImportError\u001b[0m                               Traceback (most recent call last)",
      "\u001b[1;32m<ipython-input-1-5124c54c7891>\u001b[0m in \u001b[0;36m<module>\u001b[1;34m()\u001b[0m\n\u001b[1;32m----> 1\u001b[1;33m \u001b[1;32mimport\u001b[0m \u001b[0myeob\u001b[0m \u001b[1;32mas\u001b[0m \u001b[0mchkp\u001b[0m\u001b[1;33m\u001b[0m\u001b[0m\n\u001b[0m\u001b[0;32m      2\u001b[0m \u001b[1;32mimport\u001b[0m \u001b[0mnumpy\u001b[0m \u001b[1;32mas\u001b[0m \u001b[0mnp\u001b[0m\u001b[1;33m\u001b[0m\u001b[0m\n\u001b[0;32m      3\u001b[0m \u001b[0mnp\u001b[0m\u001b[1;33m.\u001b[0m\u001b[0mset_printoptions\u001b[0m\u001b[1;33m(\u001b[0m\u001b[0mthreshold\u001b[0m\u001b[1;33m=\u001b[0m\u001b[0mnp\u001b[0m\u001b[1;33m.\u001b[0m\u001b[0minf\u001b[0m\u001b[1;33m)\u001b[0m\u001b[1;33m\u001b[0m\u001b[0m\n\u001b[0;32m      4\u001b[0m \u001b[0mchkp\u001b[0m\u001b[1;33m.\u001b[0m\u001b[0mprint_tensors_in_checkpoint_file\u001b[0m\u001b[1;33m(\u001b[0m\u001b[1;34m'c:\\\\Users\\\\kingjy79\\\\Documents\\\\rlawhdduq1\\\\emotion\\\\emotion\\\\data\\\\Gudi_model_100_epochs_20000_faces'\u001b[0m\u001b[1;33m,\u001b[0m \u001b[0mtensor_name\u001b[0m\u001b[1;33m=\u001b[0m\u001b[1;34m'Conv2D_1/W'\u001b[0m\u001b[1;33m,\u001b[0m \u001b[0mall_tensors\u001b[0m\u001b[1;33m=\u001b[0m\u001b[1;32mFalse\u001b[0m\u001b[1;33m)\u001b[0m\u001b[1;33m\u001b[0m\u001b[0m\n",
      "\u001b[1;32m~\\Documents\\rlawhdduq1\\emotion\\emotion\\yeob.py\u001b[0m in \u001b[0;36m<module>\u001b[1;34m()\u001b[0m\n\u001b[0;32m     23\u001b[0m \u001b[1;32mimport\u001b[0m \u001b[0mnumpy\u001b[0m \u001b[1;32mas\u001b[0m \u001b[0mnp\u001b[0m\u001b[1;33m\u001b[0m\u001b[0m\n\u001b[0;32m     24\u001b[0m \u001b[1;33m\u001b[0m\u001b[0m\n\u001b[1;32m---> 25\u001b[1;33m \u001b[1;32mfrom\u001b[0m \u001b[0mtensorflow\u001b[0m\u001b[1;33m.\u001b[0m\u001b[0mpython\u001b[0m \u001b[1;32mimport\u001b[0m \u001b[0mpywrap_tensorflow\u001b[0m\u001b[1;33m\u001b[0m\u001b[0m\n\u001b[0m\u001b[0;32m     26\u001b[0m \u001b[1;32mfrom\u001b[0m \u001b[0mtensorflow\u001b[0m\u001b[1;33m.\u001b[0m\u001b[0mpython\u001b[0m\u001b[1;33m.\u001b[0m\u001b[0mplatform\u001b[0m \u001b[1;32mimport\u001b[0m \u001b[0mapp\u001b[0m\u001b[1;33m\u001b[0m\u001b[0m\n\u001b[0;32m     27\u001b[0m \u001b[1;32mfrom\u001b[0m \u001b[0mtensorflow\u001b[0m\u001b[1;33m.\u001b[0m\u001b[0mpython\u001b[0m\u001b[1;33m.\u001b[0m\u001b[0mplatform\u001b[0m \u001b[1;32mimport\u001b[0m \u001b[0mflags\u001b[0m\u001b[1;33m\u001b[0m\u001b[0m\n",
      "\u001b[1;32m~\\anaconda\\lib\\site-packages\\tensorflow\\__init__.py\u001b[0m in \u001b[0;36m<module>\u001b[1;34m()\u001b[0m\n\u001b[0;32m     22\u001b[0m \u001b[1;33m\u001b[0m\u001b[0m\n\u001b[0;32m     23\u001b[0m \u001b[1;31m# pylint: disable=g-bad-import-order\u001b[0m\u001b[1;33m\u001b[0m\u001b[1;33m\u001b[0m\u001b[0m\n\u001b[1;32m---> 24\u001b[1;33m \u001b[1;32mfrom\u001b[0m \u001b[0mtensorflow\u001b[0m\u001b[1;33m.\u001b[0m\u001b[0mpython\u001b[0m \u001b[1;32mimport\u001b[0m \u001b[0mpywrap_tensorflow\u001b[0m  \u001b[1;31m# pylint: disable=unused-import\u001b[0m\u001b[1;33m\u001b[0m\u001b[0m\n\u001b[0m\u001b[0;32m     25\u001b[0m \u001b[1;31m# pylint: disable=wildcard-import\u001b[0m\u001b[1;33m\u001b[0m\u001b[1;33m\u001b[0m\u001b[0m\n\u001b[0;32m     26\u001b[0m \u001b[1;32mfrom\u001b[0m \u001b[0mtensorflow\u001b[0m\u001b[1;33m.\u001b[0m\u001b[0mtools\u001b[0m\u001b[1;33m.\u001b[0m\u001b[0mapi\u001b[0m\u001b[1;33m.\u001b[0m\u001b[0mgenerator\u001b[0m\u001b[1;33m.\u001b[0m\u001b[0mapi\u001b[0m \u001b[1;32mimport\u001b[0m \u001b[1;33m*\u001b[0m  \u001b[1;31m# pylint: disable=redefined-builtin\u001b[0m\u001b[1;33m\u001b[0m\u001b[0m\n",
      "\u001b[1;32m~\\anaconda\\lib\\site-packages\\tensorflow\\python\\__init__.py\u001b[0m in \u001b[0;36m<module>\u001b[1;34m()\u001b[0m\n\u001b[0;32m     47\u001b[0m \u001b[1;32mimport\u001b[0m \u001b[0mnumpy\u001b[0m \u001b[1;32mas\u001b[0m \u001b[0mnp\u001b[0m\u001b[1;33m\u001b[0m\u001b[0m\n\u001b[0;32m     48\u001b[0m \u001b[1;33m\u001b[0m\u001b[0m\n\u001b[1;32m---> 49\u001b[1;33m \u001b[1;32mfrom\u001b[0m \u001b[0mtensorflow\u001b[0m\u001b[1;33m.\u001b[0m\u001b[0mpython\u001b[0m \u001b[1;32mimport\u001b[0m \u001b[0mpywrap_tensorflow\u001b[0m\u001b[1;33m\u001b[0m\u001b[0m\n\u001b[0m\u001b[0;32m     50\u001b[0m \u001b[1;33m\u001b[0m\u001b[0m\n\u001b[0;32m     51\u001b[0m \u001b[1;31m# Protocol buffers\u001b[0m\u001b[1;33m\u001b[0m\u001b[1;33m\u001b[0m\u001b[0m\n",
      "\u001b[1;32m~\\anaconda\\lib\\site-packages\\tensorflow\\python\\pywrap_tensorflow.py\u001b[0m in \u001b[0;36m<module>\u001b[1;34m()\u001b[0m\n\u001b[0;32m     72\u001b[0m \u001b[1;32mfor\u001b[0m \u001b[0msome\u001b[0m \u001b[0mcommon\u001b[0m \u001b[0mreasons\u001b[0m \u001b[1;32mand\u001b[0m \u001b[0msolutions\u001b[0m\u001b[1;33m.\u001b[0m  \u001b[0mInclude\u001b[0m \u001b[0mthe\u001b[0m \u001b[0mentire\u001b[0m \u001b[0mstack\u001b[0m \u001b[0mtrace\u001b[0m\u001b[1;33m\u001b[0m\u001b[0m\n\u001b[0;32m     73\u001b[0m above this error message when asking for help.\"\"\" % traceback.format_exc()\n\u001b[1;32m---> 74\u001b[1;33m   \u001b[1;32mraise\u001b[0m \u001b[0mImportError\u001b[0m\u001b[1;33m(\u001b[0m\u001b[0mmsg\u001b[0m\u001b[1;33m)\u001b[0m\u001b[1;33m\u001b[0m\u001b[0m\n\u001b[0m\u001b[0;32m     75\u001b[0m \u001b[1;33m\u001b[0m\u001b[0m\n\u001b[0;32m     76\u001b[0m \u001b[1;31m# pylint: enable=wildcard-import,g-import-not-at-top,unused-import,line-too-long\u001b[0m\u001b[1;33m\u001b[0m\u001b[1;33m\u001b[0m\u001b[0m\n",
      "\u001b[1;31mImportError\u001b[0m: Traceback (most recent call last):\n  File \"C:\\Users\\kingjy79\\anaconda\\lib\\site-packages\\tensorflow\\python\\pywrap_tensorflow_internal.py\", line 14, in swig_import_helper\n    return importlib.import_module(mname)\n  File \"C:\\Users\\kingjy79\\anaconda\\lib\\importlib\\__init__.py\", line 126, in import_module\n    return _bootstrap._gcd_import(name[level:], package, level)\n  File \"<frozen importlib._bootstrap>\", line 985, in _gcd_import\n  File \"<frozen importlib._bootstrap>\", line 968, in _find_and_load\n  File \"<frozen importlib._bootstrap>\", line 957, in _find_and_load_unlocked\n  File \"<frozen importlib._bootstrap>\", line 666, in _load_unlocked\n  File \"<frozen importlib._bootstrap>\", line 577, in module_from_spec\n  File \"<frozen importlib._bootstrap_external>\", line 938, in create_module\n  File \"<frozen importlib._bootstrap>\", line 222, in _call_with_frames_removed\nImportError: DLL load failed: 지정된 모듈을 찾을 수 없습니다.\n\nDuring handling of the above exception, another exception occurred:\n\nTraceback (most recent call last):\n  File \"C:\\Users\\kingjy79\\anaconda\\lib\\site-packages\\tensorflow\\python\\pywrap_tensorflow.py\", line 58, in <module>\n    from tensorflow.python.pywrap_tensorflow_internal import *\n  File \"C:\\Users\\kingjy79\\anaconda\\lib\\site-packages\\tensorflow\\python\\pywrap_tensorflow_internal.py\", line 17, in <module>\n    _pywrap_tensorflow_internal = swig_import_helper()\n  File \"C:\\Users\\kingjy79\\anaconda\\lib\\site-packages\\tensorflow\\python\\pywrap_tensorflow_internal.py\", line 16, in swig_import_helper\n    return importlib.import_module('_pywrap_tensorflow_internal')\n  File \"C:\\Users\\kingjy79\\anaconda\\lib\\importlib\\__init__.py\", line 126, in import_module\n    return _bootstrap._gcd_import(name[level:], package, level)\nImportError: No module named '_pywrap_tensorflow_internal'\n\n\nFailed to load the native TensorFlow runtime.\n\nSee https://www.tensorflow.org/install/install_sources#common_installation_problems\n\nfor some common reasons and solutions.  Include the entire stack trace\nabove this error message when asking for help."
     ]
    }
   ],
   "source": [
    "import yeob as chkp\n",
    "import numpy as np\n",
    "np.set_printoptions(threshold=np.inf)\n",
    "chkp.print_tensors_in_checkpoint_file('c:\\\\Users\\\\kingjy79\\\\Documents\\\\rlawhdduq1\\\\emotion\\\\emotion\\\\data\\\n",
    "\\\\Gudi_model_100_epochs_20000_faces', tensor_name='Conv2D_1/W', all_tensors=False)\n"
   ]
  },
  {
   "cell_type": "code",
   "execution_count": null,
   "metadata": {},
   "outputs": [],
   "source": []
  }
 ],
 "metadata": {
  "kernelspec": {
   "display_name": "Python 3",
   "language": "python",
   "name": "python3"
  },
  "language_info": {
   "codemirror_mode": {
    "name": "ipython",
    "version": 3
   },
   "file_extension": ".py",
   "mimetype": "text/x-python",
   "name": "python",
   "nbconvert_exporter": "python",
   "pygments_lexer": "ipython3",
   "version": "3.5.5"
  },
  "widgets": {
   "state": {},
   "version": "1.1.2"
  }
 },
 "nbformat": 4,
 "nbformat_minor": 2
}
